{
 "cells": [
  {
   "cell_type": "code",
   "execution_count": 1,
   "id": "369191be",
   "metadata": {},
   "outputs": [],
   "source": [
    "import setup\n",
    "setup.init()"
   ]
  },
  {
   "cell_type": "code",
   "execution_count": 2,
   "id": "229410dc",
   "metadata": {},
   "outputs": [],
   "source": [
    "from ai.tools import get_document,documents_list"
   ]
  },
  {
   "cell_type": "code",
   "execution_count": 3,
   "id": "42768362",
   "metadata": {},
   "outputs": [],
   "source": [
    "config = { \"user_id\": 1}\n"
   ]
  },
  {
   "cell_type": "code",
   "execution_count": 4,
   "id": "cc1276cb",
   "metadata": {},
   "outputs": [
    {
     "name": "stdout",
     "output_type": "stream",
     "text": [
      "{'tags': [], 'metadata': {'user_id': 1}, 'callbacks': None, 'recursion_limit': 25, 'configurable': {'user_id': 1}}\n"
     ]
    },
    {
     "data": {
      "text/plain": [
       "[{'id': 1, 'title': 'Title'}, {'id': 2, 'title': 'doc 2'}]"
      ]
     },
     "execution_count": 4,
     "metadata": {},
     "output_type": "execute_result"
    }
   ],
   "source": [
    "\n",
    "documents_list.invoke(None,config)"
   ]
  },
  {
   "cell_type": "code",
   "execution_count": 10,
   "id": "e78a2a90",
   "metadata": {},
   "outputs": [
    {
     "data": {
      "text/plain": [
       "{'id': 2, 'title': 'doc 2'}"
      ]
     },
     "execution_count": 10,
     "metadata": {},
     "output_type": "execute_result"
    }
   ],
   "source": [
    "get_document.invoke({\"document_id\":2},config)"
   ]
  },
  {
   "cell_type": "code",
   "execution_count": 3,
   "id": "383962b8",
   "metadata": {},
   "outputs": [
    {
     "ename": "OperationalError",
     "evalue": "connection failed: connection to server at \"142.54.189.108\", port 5432 failed: server closed the connection unexpectedly\n\tThis probably means the server terminated abnormally\n\tbefore or while processing the request.",
     "output_type": "error",
     "traceback": [
      "\u001b[31m---------------------------------------------------------------------------\u001b[39m",
      "\u001b[31mOperationalError\u001b[39m                          Traceback (most recent call last)",
      "\u001b[36mCell\u001b[39m\u001b[36m \u001b[39m\u001b[32mIn[3]\u001b[39m\u001b[32m, line 3\u001b[39m\n\u001b[32m      1\u001b[39m \u001b[38;5;28;01mimport\u001b[39;00m\u001b[38;5;250m \u001b[39m\u001b[34;01mpsycopg\u001b[39;00m\n\u001b[32m----> \u001b[39m\u001b[32m3\u001b[39m conn = \u001b[43mpsycopg\u001b[49m\u001b[43m.\u001b[49m\u001b[43mconnect\u001b[49m\u001b[43m(\u001b[49m\u001b[33;43m\"\u001b[39;49m\u001b[33;43mpostgresql://postgres.xzjoyqcwavjlaozbimto:Sina121212SB\u001b[39;49m\u001b[38;5;132;43;01m%24%\u001b[39;49;00m\u001b[33;43m24@aws-0-eu-central-1.pooler.supabase.com:5432/postgres\u001b[39;49m\u001b[33;43m\"\u001b[39;49m\u001b[43m)\u001b[49m\n\u001b[32m      4\u001b[39m \u001b[38;5;28mprint\u001b[39m(\u001b[33m\"\u001b[39m\u001b[33mConnected successfully!\u001b[39m\u001b[33m\"\u001b[39m)\n\u001b[32m      5\u001b[39m conn.close()\n",
      "\u001b[36mFile \u001b[39m\u001b[32mc:\\Users\\SOURCE\\AppData\\Local\\Programs\\Python\\Python312\\Lib\\site-packages\\psycopg\\connection.py:118\u001b[39m, in \u001b[36mConnection.connect\u001b[39m\u001b[34m(cls, conninfo, autocommit, prepare_threshold, context, row_factory, cursor_factory, **kwargs)\u001b[39m\n\u001b[32m    116\u001b[39m last_ex = conn_errors[-\u001b[32m1\u001b[39m][\u001b[32m0\u001b[39m]\n\u001b[32m    117\u001b[39m \u001b[38;5;28;01mif\u001b[39;00m \u001b[38;5;28mlen\u001b[39m(conn_errors) == \u001b[32m1\u001b[39m:\n\u001b[32m--> \u001b[39m\u001b[32m118\u001b[39m     \u001b[38;5;28;01mraise\u001b[39;00m last_ex.with_traceback(\u001b[38;5;28;01mNone\u001b[39;00m)\n\u001b[32m    120\u001b[39m \u001b[38;5;66;03m# Create a new exception with the same type as the last one, containing\u001b[39;00m\n\u001b[32m    121\u001b[39m \u001b[38;5;66;03m# all attempt errors while preserving backward compatibility.\u001b[39;00m\n\u001b[32m    122\u001b[39m lines = [\u001b[38;5;28mstr\u001b[39m(last_ex)]\n",
      "\u001b[31mOperationalError\u001b[39m: connection failed: connection to server at \"142.54.189.108\", port 5432 failed: server closed the connection unexpectedly\n\tThis probably means the server terminated abnormally\n\tbefore or while processing the request."
     ]
    }
   ],
   "source": [
    "import psycopg\n",
    "\n",
    "conn = psycopg.connect(\"postgresql://postgres.xzjoyqcwavjlaozbimto:Sina121212SB%24%24@aws-0-eu-central-1.pooler.supabase.com:5432/postgres\")\n",
    "print(\"Connected successfully!\")\n",
    "conn.close()\n"
   ]
  }
 ],
 "metadata": {
  "kernelspec": {
   "display_name": "Python 3",
   "language": "python",
   "name": "python3"
  },
  "language_info": {
   "codemirror_mode": {
    "name": "ipython",
    "version": 3
   },
   "file_extension": ".py",
   "mimetype": "text/x-python",
   "name": "python",
   "nbconvert_exporter": "python",
   "pygments_lexer": "ipython3",
   "version": "3.12.5"
  }
 },
 "nbformat": 4,
 "nbformat_minor": 5
}
